Workbook

Sheet Backlog
A1: Riviso — Production Hardening & Scale Tracker (Target ~50 users)
A2: Phase | B2: ID | C2: Category | D2: Item | E2: Severity / Priority | F2: Effort | G2: Evidence (file:line) | H2: Fix / Action | I2: Verification | J2: Status | K2: Owner | L2: Notes
A3: PHASE 0 — Critical Security (stop-the-bleed)
A4: P0 | B4: S0.1 | C4: Security | D4: Fail-fast on placeholder/short SECRET_KEY in production | E4: Critical | F4: S | G4: core/config.py:47-49; core/production.py:67-71 | H4: Raise at startup if ENVIRONMENT=production and key is default or <32 chars | I4: Boot with bad key exits non-zero | J4: Not Started
A5: P0 | B5: S0.2 | C5: Security | D5: Remove hardcoded admin seed 'Admin@2026' | E5: Critical | F5: S | G5: app.py:52-78 | H5: Delete seed; env-gated one-time bootstrap CLI | I5: grep finds no literal password; fresh DB has no default admin | J5: Not Started
A6: P0 | B6: S0.3 | C6: Security | D6: Stop returning WordPress app password in API responses | E6: High | F6: S | G6: routes/wordpress.py:537,584-585; schemas/project_settings.py:34-36 | H6: Return wp_app_password_set: bool only | I6: Response JSON contains no secret | J6: Not Started
A7: P0 | B7: S0.4 | C7: Security | D7: Disallow MONGODB_TLS_INSECURE & OAUTHLIB_INSECURE_TRANSPORT in prod | E7: High | F7: S | G7: database.py:88-93; app.py:33-36 | H7: Startup check rejects insecure transport in production | I7: Prod boot fails if flags set | J7: Not Started
A8: P0 | B8: S0.5 | C8: Security | D8: Confirm legacy Flask app.py is not deployed/reachable | E8: High | F8: M | G8: app.py (whole) | H8: Remove from deploy target or gate behind disabled flag | I8: No prod route served by Flask | J8: Not Started
A9: PHASE 1 — Security Hardening
A10: P1 | B10: S1.1 | C10: Security | D10: Refresh-token rotation + server-side invalidation | E10: High | F10: M | G10: routes/auth.py:700-790 | H10: Issue new RT each refresh; track jti allow/deny list | I10: Reused old RT is rejected | J10: Not Started
A11: P1 | B11: S1.2 | C11: Security | D11: Rate-limit /auth/refresh | E11: High | F11: S | G11: routes/auth.py:700 | H11: @limiter.limit('20/minute') | I11: 429 after threshold | J11: Not Started
A12: P1 | B12: S1.3 | C12: Security | D12: Move JWT tokens out of localStorage to httpOnly cookies | E12: High | F12: M | G12: frontend/src/lib/api.ts:1038-1060,1282-1347 | H12: Cookie-only auth; remove localStorage | I12: No tokens in localStorage; XSS cannot read | J12: Not Started
A13: P1 | B13: S1.4 | C13: Security | D13: Cookie Secure default true in prod + max_age aligned to TTL | E13: Medium | F13: S | G13: core/config.py:53; routes/auth.py:127-163,772-788 | H13: Secure+SameSite+expiry | I13: Cookies have Secure+expiry in prod | J13: Not Started
A14: P1 | B14: S1.5 | C14: Security | D14: Account lockout after N failed logins | E14: Medium | F14: M | G14: routes/auth.py:187 | H14: Per-email backoff/lockout | I14: Lockout triggers in test | J14: Not Started
A15: P1 | B15: S1.6a | C15: Security | D15: SSRF guard on WordPress URL fetch (block private/metadata IPs) | E15: High | F15: M | G15: routes/wordpress.py:140-146; services/wordpress_client.py:45-81 | H15: URL allowlist + IP guard; restrict redirects | I15: Request to 169.254.169.254 / 10.x blocked | J15: Not Started
A16: P1 | B16: S1.6b | C16: Security | D16: SSRF guard on Shopify shop resolution | E16: High | F16: M | G16: services/shopify_oauth.py:132-137 | H16: Require *.myshopify.com / Admin API only | I16: Non-shopify host rejected | J16: Not Started
A17: P1 | B17: S1.6c | C17: Security | D17: SSRF guard on featured-image + OpenAI ref-image download | E17: High | F17: M | G17: services/wordpress_client.py:231-237; services/shopify_article_image.py:47-61; services/openai_client.py:175-178 | H17: HTTPS host allowlist / data-URL only | I17: Internal IP fetch blocked | J17: Not Started
A18: P1 | B18: S1.7 | C18: Security | D18: CSRF protection for cookie auth | E18: Medium | F18: M | G18: core/deps.py:38-46 | H18: Require X-Requested-With on mutations or SameSite=Strict | I18: Cross-site POST without header rejected | J18: Not Started
A19: P1 | B19: S1.8 | C19: Security | D19: Drop localhost origins from production CORS | E19: Medium | F19: S | G19: main.py:72-87,234-240 | H19: Env-only strict allowlist in production | I19: Prod CORS excludes localhost | J19: Not Started
A20: P1 | B20: S1.9 | C20: Security | D20: Rate-limit expensive endpoints (generate/bulk-upload/publish/research) | E20: Medium | F20: M | G20: core/ratelimit.py:13 | H20: Per-user limits on OpenAI-backed routes | I20: 429 after threshold per user | J20: Not Started
A21: P1 | B21: S1.10 | C21: Security | D21: Trust-proxy config so rate-limit key is not XFF-spoofable | E21: Medium | F21: S | G21: core/ratelimit.py:11-13 | H21: Configure trusted proxy or key by user id | I21: Spoofed XFF does not bypass limit | J21: Not Started
... A25: P1 | B25: S1.14 | C25: Security | D25: Add Next.js security headers | E25: Low | F25: S | G25: frontend/next.config.ts:15-27 | H25: headers() with HSTS/CSP/X-Frame | I25: Headers present on frontend responses | J25: Not Started
A26: PHASE 2 — Performance Quick Wins
A27: P2 | B27: P2.1 | C27: Performance | D27: Request-scoped cache for user/subscription/plan | E27: High | F27: M | G27: core/deps.py:58-60; middleware/plan_limits.py:79-90; services/plan_gatekeeper.py:92-97 | H27: Attach to request.state; gatekeeper reads it | I27: 1 user read per request (not 3-5) | J27: Not Started
A28: P2 | B28: P2.2 | C28: Performance | D28: TTL cache for load_plans() | E28: Medium | F28: S | G28: storage.py:1205; services/plan_gatekeeper.py:49-58 | H28: Module cache ~60s invalidated on upsert_plan | I28: Plans read once per TTL window | J28: Not Started
A29: P2 | B29: P2.3 | C29: Performance | D29: Wrap all sync storage in run_sync on hot async paths | E29: High | F29: M | G29: core/deps.py:58-60; core/project_lookup.py:27-45; routes/wordpress.py:470 | H29: await run_sync(...) everywhere | I29: No sync PyMongo on event loop (profiler) | J29: Not Started
A30: P2 | B30: P2.4 | C30: Performance | D30: Add load_articles_by_ids_for_project; drop 20k scans | E30: High | F30: M | G30: routes/articles.py:1028-1037; routes/scheduled_jobs.py:246-256 | H30: $in query batch fetch | I30: Bulk validate uses single $in query | J30: Not Started
A31: P2 | B31: P2.5 | C31: Performance | D31: asyncio.gather serial pairs (editor-shell, board, shopify sync) | E31: Medium | F31: M | G31: routes/articles.py:1248-1262; routes/scheduled_jobs.py:284-295; services/shopify_sync.py:196-250 | H31: Concurrent independent awaits | I31: Latency = max not sum | J31: Not Started
A32: P2 | B32: P2.6 | C32: Frontend | D32: Visibility guard + backoff on all poll loops | E32: Medium | F32: M | G32: frontend/src/lib/api.ts:788-844; app/projects/[projectId]/page.tsx:1763-1774,3096-3120 | H32: document.hidden check + backoff | I32: No polling when tab hidden | J32: Not Started
A33: P2 | B33: P2.7 | C33: Frontend | D33: Replace listArticlesAll waterfall with aggregate endpoint | E33: High | F33: M | G33: frontend/src/lib/api.ts:1963-1975; page.tsx:1283-1322 | H33: Use workspaceOverview() | I33: Overview loads 1 request not 50 | J33: Not Started
A34: P2 | B34: P2.8 | C34: Frontend | D34: Stop shell refetch on tab switch; dedupe GSC analytics | E34: Medium | F34: S | G34: page.tsx:1171-1218,1290-1372,2508-2521 | H34: Drop tab from deps; share analytics in state | I34: Tab switch fires no shell refetch | J34: Not Started
A35: PHASE 3 — Infrastructure for ~50 Users
A36: P3 | B36: I3.1 | C36: Infrastructure | D36: Separate worker & scheduler from API processes | E36: High | F36: M | G36: main.py:129-138 (lifespan); Procfile | H36: API ENABLE_SCHEDULER=0/worker=0 + 1 worker + 1 scheduler proc | I36: API process runs no scheduler/worker | J36: Not Started
A37: P3 | B37: I3.2 | C37: Infrastructure | D37: Managed MongoDB Atlas M10 (TLS, IP allowlist, backups) | E37: High | F37: M | G37: database.py:88-93 | H37: Atlas M10, TLS on, maxIdleTimeMS=30000 | I37: App connects to M10 over TLS | J37: Not Started
A38: P3 | B38: I3.3 | C38: Infrastructure | D38: Managed Redis (auth + TLS) | E38: High | F38: S | G38: services/generation_queue.py | H38: Single managed Redis with auth/TLS | I38: Queue uses managed Redis | J38: Not Started
A39: P3 | B39: I3.4 | C39: Infrastructure | D39: Automated daily backups + tested restore | E39: High | F39: S | G39: Atlas / ops | H39: Continuous backup; quarterly restore drill | I39: Restore drill succeeds | J39: Not Started
A40: P3 | B40: I3.5 | C40: Infrastructure | D40: TLS termination + HSTS + gzip at Nginx/Cloudflare | E40: High | F40: S | G40: nginx/ | H40: Force HTTPS redirect + HSTS | I40: HTTP redirects to HTTPS; HSTS header set | J40: Not Started
A41: P3 | B41: I3.6 | C41: Infrastructure | D41: Connection pool sizing across processes | E41: Medium | F41: S | G41: database.py | H41: Set maxPoolSize per process; sum < Atlas limit | I41: No connection-limit errors under load | J41: Not Started
A42: P3 | B42: I3.7 | C42: Infrastructure | D42: Healthchecks + auto-restart (liveness/readiness) | E42: Medium | F42: S | G42: routes/health.py | H42: Container healthcheck -> restart policy | I42: Killed proc auto-restarts | J42: Not Started
A43: P3 | B43: I3.8 | C43: Infrastructure | D43: 2-instance API behind LB + rolling deploy | E43: Medium | F43: M | G43: deploy/ | H43: 2 small API instances; zero-downtime deploy | I43: Deploy with no downtime | J43: Not Started
...

Sheet Dashboard
A1: Progress Dashboard
A3: By Status | B3: Count
A4: Not Started | B4: =COUNTIF(Backlog!$J$3:$J$70,"Not Started")
A5: In Progress | B5: =COUNTIF(Backlog!$J$3:$J$70,"In Progress")
A6: Blocked | B6: =COUNTIF(Backlog!$J$3:$J$70,"Blocked")
A7: In Review | B7: =COUNTIF(Backlog!$J$3:$J$70,"In Review")
A8: Done | B8: =COUNTIF(Backlog!$J$3:$J$70,"Done")
A9: Deferred | B9: =COUNTIF(Backlog!$J$3:$J$70,"Deferred")
A10: TOTAL TASKS | B10: =COUNTA(Backlog!$B$3:$B$70)-COUNTBLANK(Backlog!$B$3:$B$70)
A12: % Complete | B12: =IFERROR(COUNTIF(Backlog!$J$3:$J$70,"Done")/B10,0)
A15: By Phase | B15: Total | C15: Done
A16: PHASE 0 — Critical Security (stop-the-bleed) | B16: =COUNTIFS(Backlog!$A$3:$A$70,"P0",Backlog!$J$3:$J$70,"<>") | C16: =COUNTIFS(Backlog!$A$3:$A$70,"P0",Backlog!$J$3:$J$70,"Done")
A17: PHASE 1 — Security Hardening | B17: =COUNTIFS(Backlog!$A$3:$A$70,"P1",Backlog!$J$3:$J$70,"<>") | C17: =COUNTIFS(Backlog!$A$3:$A$70,"P1",Backlog!$J$3:$J$70,"Done")
A18: PHASE 2 — Performance Quick Wins | B18: =COUNTIFS(Backlog!$A$3:$A$70,"P2",Backlog!$J$3:$J$70,"<>") | C18: =COUNTIFS(Backlog!$A$3:$A$70,"P2",Backlog!$J$3:$J$70,"Done")
A19: PHASE 3 — Infrastructure for ~50 Users | B19: =COUNTIFS(Backlog!$A$3:$A$70,"P3",Backlog!$J$3:$J$70,"<>") | C19: =COUNTIFS(Backlog!$A$3:$A$70,"P3",Backlog!$J$3:$J$70,"Done")
A20: PHASE 4 — Structural Refactor (data / OOP layer) | B20: =COUNTIFS(Backlog!$A$3:$A$70,"P4",Backlog!$J$3:$J$70,"<>") | C20: =COUNTIFS(Backlog!$A$3:$A$70,"P4",Backlog!$J$3:$J$70,"Done")
A21: PHASE 5 — Observability, Testing & CI | B21: =COUNTIFS(Backlog!$A$3:$A$70,"P5",Backlog!$J$3:$J$70,"<>") | C21: =COUNTIFS(Backlog!$A$3:$A$70,"P5",Backlog!$J$3:$J$70,"Done")
A22: PHASE 6 — Launch Readiness | B22: =COUNTIFS(Backlog!$A$3:$A$70,"P6",Backlog!$J$3:$J$70,"<>") | C22: =COUNTIFS(Backlog!$A$3:$A$70,"P6",Backlog!$J$3:$J$70,"Done")

Sheet Legend
A1: Legend & Conventions
A3: Severity
A4: Critical | B4: Exploitable now / secrets exposed — fix before anything else
A5: High | B5: Serious risk or large perf/scale impact — Phase 0/1/2
A6: Medium | B6: Important, bounded impact — schedule within phase
A7: Low | B7: Cleanup / future-proofing
A9: Effort
A10: S | B10: Small — < 1 day
A11: M | B11: Medium — 1-3 days
A12: L | B12: Large — 1 week+
A14: Status values | B14: Not Started, In Progress, Blocked, In Review, Done, Deferred
A15: ID prefix S | B15: Security item (see RIVISO_PRODUCTION_HARDENING_PLAN.md §A)
A16: ID prefix P2/P4 | B16: Performance item (see RIVISO_PERFORMANCE_OPTIMIZATION_AUDIT.md)
A17: ID prefix I | B17: Infrastructure / Ops item
A18: ID prefix L | B18: Launch readiness item
A19: Evidence | B19: Backend paths are relative to backend/app unless app.py/storage.py/database.py (repo root)
